<?xml version="1.0"?> 
<gazebo version="1.0">
	<world name="default">
		<scene>
			<ambient rgba="1.0 1.0 1.0 1"/>
			<background rgba="0 0 0 1.0"/>
			<shadows enabled="false"/>
			<grid enabled="false" />
		</scene>

		<physics type="ode" update_rate="1000">
			<gravity xyz="0 0 -9.81"/>
			<ode>
				<solver type="quick" dt="0.001" iters="1000" sor="1.3"/>
				<constraints cfm="0.0000000001" erp="0.2" contact_max_correcting_vel="100.0" contact_surface_layer="0.001"/>
			</ode>
		</physics>


		<light type="directional" name="sun" cast_shadows="true">
			<origin pose="0 0 10 0 0 0"/>
			<diffuse rgba=".8 .8 .8 1"/>
			<specular rgba=".1 .1 .1 1"/>
			<attenuation range="10" constant="0.8" linear="0.01" quadratic="0.0"/>
			<direction xyz="0 .5 -.5"/>
		</light>

		<!-- Ground Plane -->
		<model name="plane_model" static="true">
			<link name="body">
			<collision name="geom">
				<geometry>
					<plane normal="0 0 1"/>
				</geometry>
				<surface>
					<friction>
						<ode mu="100000.0" mu2="100000.0"/>
					</friction>
				</surface>
			</collision>

			<visual name="visual" cast_shadows="false">
				<geometry>
					<plane normal="0 0 1"/>
				</geometry>
				<material script="Kitchen/Grass"/>
			</visual>
			</link>
		</model>


		<!-- ATRIAS -->
		<model name="ATRIAS_model" static="false">
			<origin pose="0 0 1.2 0 0 0"/>


			<!-- Body -->
			<link name="body_link" gravity="1" self_collide="0">
			<origin pose="0 0 0 0 0 0"/>

			<inertial mass="11.61">
				<origin pose="0 0 0 0 0 0"/>
				<inertia ixx="0.0932" ixy="0.0044" ixz="-0.0019" iyy="0.0833" iyz="-0.0102" izz="0.0785"/>
			</inertial>
				
			<collision name="collision">
				<origin pose="0 0 0 0 0 0"/>
				<geometry>
					<box size="0.25 0.15 0.15"/>
				</geometry>
				<surface>
					<contact>
						<ode soft_erp="1" max_vel="0"/>
					</contact>
				</surface>
			</collision>

			<visual name="visual">
				<origin pose="0 0 0 0 0 0"/>
				<geometry>
					<box size="0.25 0.15 0.15"/>
				</geometry>
				<material script="Gazebo/Grey"/>
			</visual>

			</link>


			<!-- Thigh Motor -->
			<link name="thigh_motor_link" gravity="1" self_collide="0">
				<origin pose="0 0 0 0 0 0"/>

				<inertial mass="1.273">
					<origin pose="0 0.044 0 0 0 0"/>
					<inertia ixx="4" ixy="0" ixz="0" iyy="7.25" iyz="0" izz="4"/>
				</inertial>
					
				<collision name="collision">
					<origin pose="0 0 0 0 0.785 0"/>
					<geometry>
						<cylinder length="0.4" radius="0.021"/>
					</geometry>
					<surface>
						<contact>
							<ode soft_erp="1" max_vel="0"/>
						</contact>
					</surface>
				</collision>

				<visual name="visual">
					<origin pose="0 0 0 0 0.785 0"/>
					<geometry>
						<cylinder length="0.4" radius="0.021"/>
					</geometry>
					<material script="Gazebo/Green"/>
				</visual>

			</link>


			<!-- Shin Motor -->
			<link name="shin_motor_link" gravity="1" self_collide="0">
				<origin pose="0 0 0 0 0 0"/>

				<inertial mass="1.273">
					<origin pose="0 -0.044 0 0 0 0"/>
					<inertia ixx="4" ixy="0" ixz="0" iyy="7.25" iyz="0" izz="4"/>
				</inertial>
					
				<collision name="collision">
					<origin pose="0 0 0 0 -0.785 0"/>
					<geometry>
						<cylinder length="0.4" radius="0.021"/>
					</geometry>
					<surface>
						<contact>
							<ode soft_erp="1" max_vel="0"/>
						</contact>
					</surface>
				</collision>

				<visual name="visual">
					<origin pose="0 0 0 0 -0.785 0"/>
					<geometry>
						<cylinder length="0.4" radius="0.021"/>
					</geometry>
					<material script="Gazebo/Green"/>
				</visual>

			</link>


			<!-- Thigh -->
			<link name="thigh_link" gravity="1" self_collide="0">
				<origin pose="0 0 0 0 0 0"/>

				<inertial mass="3.132">
					<origin pose="-0.1 -0.0056 -0.0179 0 0 0"/>
					<inertia ixx="0.0339" ixy="0.0056" ixz="-0.0179" iyy="0.0688" iyz="-0.0017" izz="0.0512"/>
				</inertial>

				<collision name="collision">
					<origin pose="-0.177 0 -0.177 0 0.785 0"/>
					<geometry>
						<cylinder length="0.5" radius="0.02"/>
					</geometry>
					<surface>
						<contact>
							<ode soft_erp="1" max_vel="0"/>
						</contact>
					</surface>
				</collision>

				<visual name="visual">
					<origin pose="-0.177 0 -0.177 0 0.785 0"/>
					<geometry>
						<cylinder length="0.5" radius="0.02"/>
					</geometry>
					<material script="Gazebo/Red"/>
				</visual>

			</link>

			<!-- Shin -->
			<link name="shin_link" gravity="1" self_collide="0">
				<origin pose="0 0 0 0 0 0"/>

				<inertial mass="3.137">
					<origin pose="0.0979 0.0200 -0.0081 0 0 0"/>
					<inertia ixx="0.0309" ixy="0.0054" ixz="0.0154" iyy="0.0637" iyz="0.0014" izz="0.0493"/>
				</inertial>
					
				<collision name="collision">
					<origin pose="0.124 0 -0.124 0 -0.785 0"/>
					<geometry>
						<cylinder length="0.35" radius="0.02"/>
					</geometry>
					<surface>
						<contact>
							<ode soft_erp="1" max_vel="0"/>
						</contact>
					</surface>
				</collision>

				<visual name="visual">
					<origin pose="0.124 0 -0.124 0 -0.785 0"/>
					<geometry>
						<cylinder length="0.35" radius="0.02"/>
					</geometry>
					<material script="Gazebo/Red"/>
				</visual>

			</link>

			<!-- Lower Link -->
			<link name="lower_link" gravity="1" self_collide="0">
				<origin pose="-0.354 0 -0.354 0 0 0"/>

				<inertial mass="0.204">
					<origin pose="0.127 0 -0.141 0 0 0"/>
					<inertia ixx="0.0027" ixy="0" ixz="0.0026" iyy="0.0054" iyz="0" izz="0.0028"/>
				</inertial>
					
				<collision name="collision">
					<origin pose="0.177 0 -0.177 0 -0.785 0"/>
					<geometry>
						<cylinder length="0.5" radius="0.02"/>
					</geometry>
					<surface>
						<contact>
							<ode soft_erp="1" max_vel="0"/>
						</contact>
					</surface>
				</collision>

				<collision name="toe">
					<origin pose="0.354 0 -0.354 0 0 0"/>
					<geometry>
						<sphere radius="0.02"/>
					</geometry>
					<surface>
						<friction>
							<ode mu='1' mu2='1' fdir1='0.0 0.0 0.0' slip1='0.0' slip2='0.0'/>
						</friction>
						<bounce restitution_coefficient='0.0' threshold='0.0'/>
						<contact>
							<ode soft_cfm='0.0' soft_erp='0.2' kp='1e15' kd='1e13' max_vel='-1.0' min_depth='0.0001'/>
						</contact>
					</surface>
				</collision>

				<visual name="visual">
					<origin pose="0.177 0 -0.177 0 -0.785 0"/>
					<geometry>
						<cylinder length="0.5" radius="0.02"/>
					</geometry>
					<material script="Gazebo/Red"/>
				</visual>

				<visual name="toe">
					<origin pose="0.354 0 -0.354 0 0 0"/>
					<geometry>
						<sphere radius="0.02"/>
					</geometry>
					<material script="Gazebo/Red"/>
				</visual>

			</link>

			<!-- Four Bar Link -->
			<link name="fourBar_link" gravity="1" self_collide="0">
				<origin pose="0.247 0 -0.247 0 0 0"/>

				<inertial mass="0.166">
					<origin pose="-0.1633 0 -0.1633 0 0 0"/>
					<inertia ixx="0.0033" ixy="0" ixz="-0.0032" iyy="0.0063" iyz="0" izz="0.0033"/>
				</inertial>
					
				<collision name="collision">
					<origin pose="-0.177 0 -0.177 0 0.785 0"/>
					<geometry>
						<cylinder length="0.5" radius="0.02"/>
					</geometry>
					<surface>
						<contact>
							<ode soft_erp="1" max_vel="0"/>
						</contact>
					</surface>
				</collision>

				<visual name="visual">
					<origin pose="-0.177 0 -0.177 0 0.785 0"/>
					<geometry>
						<cylinder length="0.5" radius="0.02"/>
					</geometry>
					<material script="Gazebo/Red"/>
				</visual>

			</link>

			<link name="toe_link" gravity="1" self_collide="0" kinematic="0">
				<origin pose="0 0 -0.707 0 0 0"/>

				<inertial mass="0.001">
					<origin pose="0 0 0 0 0 0"/>
					<inertia ixx="0" ixy="0" ixz="0" iyy="0" iyz="0" izz="0"/>
				</inertial>
					
				<collision name="collision">
					<origin pose="0 0 0 0 0 0"/>
					<geometry>
						<sphere radius="0.01"/>
					</geometry>
					<surface>
						<contact>
							<ode soft_erp="1" max_vel="0"/>
						</contact>
					</surface>
				</collision>

				<visual name="visual">
					<origin pose="0 0 0 0 0 0"/>
					<geometry>
						<sphere radius="0.01"/>
					</geometry>
					<material script="Gazebo/Blue"/>
				</visual>

			</link>

			<!-- Joints -->
			<joint name="body_thigh_joint" type="revolute">
				<parent link="body_link"/>
				<child link="thigh_link"/>
				<origin pose="0 0 0 0 0 0"/> <!-- Defined w.r.t. the child link origin-->
				<axis xyz="0 1 0">
					<dynamics damping="0.1" friction="0.1"/>
				</axis>
			</joint>

			<joint name="body_shin_joint" type="revolute">
				<parent link="body_link"/>
				<child link="shin_link"/>
				<origin pose="0 0 0 0 0 0"/>
				<axis xyz="0 1 0">
					<dynamics damping="0.1" friction="0.1"/>
				</axis>
			</joint>

			<joint name="body_thigh_motor" type="revolute">
				<parent link="body_link"/>
				<child link="thigh_motor_link"/>
				<origin pose="0 0 0 0 0 0"/>
				<axis xyz="0 1 0">
					<dynamics damping="0" friction="0"/>
				</axis>
			</joint>

			<joint name="body_shin_motor" type="revolute">
				<parent link="body_link"/>
				<child link="shin_motor_link"/>
				<origin pose="0 0 0 0 0 0"/>
				<axis xyz="0 1 0">
					<dynamics damping="0" friction="0"/>
				</axis>
			</joint>

			<joint name="shin_fourBar_joint" type="revolute">
				<parent link="shin_link"/>
				<child link="fourBar_link"/>
				<origin pose="0 0 0 0 0 0"/>
				<axis xyz="0 1 0">
					<dynamics damping="0.1" friction="0.1"/>
				</axis>
			</joint>

			<joint name="thigh_lower_joint" type="revolute">
				<parent link="thigh_link"/>
				<child link="lower_link"/>
				<origin pose="0 0 0 0 0 0"/>
				<axis xyz="0 1 0">
					<dynamics damping="0.1" friction="0.1"/>
				</axis>
			</joint>

			<joint name="lower_fourBar_joint" type="revolute">
				<parent link="lower_link"/>
				<child link="fourBar_link"/>
				<origin pose="-0.354 0 -0.354 0 0 0"/>
				<axis xyz="0 1 0">
					<dynamics damping="0.1" friction="0.1"/>
				</axis>
			</joint>

			<joint name="lower_toe_joint" type="revolute">
				<parent link="lower_link"/>
				<child link="toe_link"/>
				<origin pose="0 0 0 0 0 0"/>
				<axis xyz="0 1 0">
					<dynamics damping="0.1" friction="0.1"/>
				</axis>
			</joint>

			<!-- Plugins -->
			<plugin name="shin_spring" filename="libspring.so">
				<link1Name>shin_motor_link</link1Name>
				<link2Name>shin_link</link2Name>
				<rotationalStiffness>1200</rotationalStiffness> <!-- N*m/rad -->
			</plugin>

			<plugin name="thigh_spring" filename="libspring.so">
				<link1Name>thigh_motor_link</link1Name>
				<link2Name>thigh_link</link2Name>
				<rotationalStiffness>1200</rotationalStiffness> <!-- N*m/rad -->
			</plugin>

		</model>


	<plugin name="pause_world" filename="libpause_world.so"/>

<!-- Note: Currently unconstrains purely the z-axis -->
<!--
	<plugin name="planar_constraint" filename="libplanar_constraint.so">
		<modelName>ATRIAS_model</modelName>
		<linkName>body_link</linkName>
	</plugin>
-->

	<plugin name="freeze_pose" filename="libfreeze_pose.so">
		<modelName>ATRIAS_model</modelName>
		<linkName>body_link</linkName>
	</plugin>

	<plugin name="atrias20_leg" filename="libatrias20_leg.so">
		<modelName>ATRIAS_model</modelName>
		<bodyName>body_link</bodyName>
		<motorAName>shin_motor_link</motorAName>
		<motorBName>thigh_motor_link</motorBName>
		<legAName>shin_link</legAName>
		<legBName>thigh_link</legBName>
		<toeName>toe_link</toeName>
	</plugin>

	</world>
</gazebo>

