<?xml version="1.0"?> 
<gazebo version="1.0">
    <world name="default">

        <scene>
            <ambient rgba="1.0 1.0 1.0 1"/>
            <background rgba="0 0 0 1.0">
                <sky material="Gazebo/CloudySky" />
            </background>
            <shadows enabled="false"/>
            <grid enabled="false" />
        </scene>

        <physics type="ode" update_rate="1000">
            <gravity xyz="0 0 -9.81"/>
            <ode>
                <solver type="quick" dt="0.001" iters="100" sor="1.3"/>
                <constraints cfm="0.0000000001" erp="0.2" contact_max_correcting_vel="100.0" contact_surface_layer="0.001"/>
            </ode>
        </physics>

        <light type="directional" name="sun" cast_shadows="true">
            <origin pose="0 0 10 0 0 0"/>
            <diffuse rgba=".8 .8 .8 1"/>
            <specular rgba=".1 .1 .1 1"/>
            <attenuation range="10" constant="0.8" linear="0.01" quadratic="0.0"/>
            <direction xyz="0 .5 -.5"/>
        </light>

        <!-- Ground Plane -->
        <include filename="grass_ground_plane.model"/>

        <!-- ATRIAS -->
        <model name="atrias20">
            <include filename="atrias20_left_leg.model" model_pose="0 0.158 1.2 0 0 0"/>
            <include filename="atrias20_right_leg.model" model_pose="0 -0.158 1.2 0 0 0"/>
            <include filename="atrias21_hip.model" model_pose="0 0 1.2 0 0 0"/>

            <!-- Central Joints -->
            <joint name="hip_to_left_leg_joint" type="revolute">
                <parent link="atrias21_hip::body_link"/>
                <child link="atrias20_left_leg::body_link"/>
                <origin pose="0 -0.158 0 0 0 0"/>
                <axis xyz="1 0 0">
                    <dynamics damping="0.1" friction="0.1"/>
                    <limit lower="-1.50" upper="1.50" effort="0.0" velocity="0.0"/>
                </axis>
            </joint>
            <joint name="hip_to_right_leg_joint" type="revolute">
                <parent link="atrias21_hip::body_link"/>
                <child link="atrias20_right_leg::body_link"/>
                <origin pose="0 0.158 0 0 0 0"/>
                <axis xyz="1 0 0">
                    <dynamics damping="0.1" friction="0.1"/>
                    <limit lower="-1.50" upper="1.50" effort="0.0" velocity="0.0"/>
                </axis>
            </joint>

            <!-- Hip Motor Joints -->
            <joint name="left_attachment_to_body_joint" type="revolute">
                <parent link="atrias20_left_leg::body_link"/>
                <child link="atrias21_hip::left_motor_attachment"/>
                <origin pose="0 0 -0.22 0 0 0"/>
                <axis xyz="1 0 0">
                    <dynamics damping="0.1" friction="0.1"/>
                </axis>
            </joint>
            <joint name="right_attachment_to_body_joint" type="revolute">
                <parent link="atrias20_right_leg::body_link"/>
                <child link="atrias21_hip::right_motor_attachment"/>
                <origin pose="0 0 -0.22 0 0 0"/>
                <axis xyz="1 0 0">
                    <dynamics damping="0.1" friction="0.1"/>
                </axis>
            </joint>
        </model>

        <plugin name="pause_world" filename="libpause_world.so"/>

        <!--
        -->
        <plugin name="freeze_pose" filename="libfreeze_pose.so">
            <modelName>atrias20</modelName>
            <linkName>atrias20_left_leg::body_link</linkName>
        </plugin>
        <plugin name="freeze_pose" filename="libfreeze_pose.so">
            <modelName>atrias20</modelName>
            <linkName>atrias20_right_leg::body_link</linkName>
        </plugin>
        <plugin name="freeze_pose" filename="libfreeze_pose.so">
            <modelName>atrias20</modelName>
            <linkName>atrias21_hip::body_link</linkName>
        </plugin>

        <plugin name="atrias20_biped" filename="libatrias20_biped.so">
            <modelName>atrias20</modelName>

            <leftLegName>atrias20_left_leg</leftLegName>
            <rightLegName>atrias20_right_leg</rightLegName>
            <hipName>atrias21_hip</hipName>

            <bodyName>body_link</bodyName>
            <motorAName>shin_motor_link</motorAName>
            <motorBName>thigh_motor_link</motorBName>
            <legAName>shin_link</legAName>
            <legBName>thigh_link</legBName>
            <toeName>toe_link</toeName>

            <hipBodyName>body_link</hipBodyName>
            <hipCenterName>hip_center</hipCenterName>
            <hipLeftMotorName>left_motor</hipLeftMotorName>
            <hipLeftMotorAttachmentName>left_motor_attachment</hipLeftMotorAttachmentName>
            <hipRightMotorName>right_motor</hipRightMotorName>
            <hipRightMotorAttachmentName>right_motor_attachment</hipRightMotorAttachmentName>
        </plugin>

    </world>
</gazebo>
